<?xml version="1.0" ?>
<robot name="simple_box">
    <link name="base_link"/>

    <joint name="base_joint" type="fixed">
        <parent link="base_link" />
        <child link="body_link1" />
    </joint>

    <link name="body_link1">
        <visual>
            <geometry>
                <box size="0.1 0.1 0.5" />
            </geometry>
            <origin xyz="0 0 0.25" rpy="0 0 0" />
            <material name="red">
                <color rgba="1.0 0.0 0.0 1.0" />
            </material>
        </visual>
    </link>

    <joint name="waist_joint" type="revolute">
        <parent link="body_link1"/>
        <child link="body_link2"/>
        <origin xyz="0.1 0 0.5" rpy="0 0 0"/>
        <limit lower="-1.5" upper="1.5" effort="0" velocity="0"/>
    </joint>

    <link name="body_link2">
        <visual>
            <geometry>
                <box size="0.1 0.1 0.5"/>
            </geometry>
            <origin xyz="0 0 0.25" rpy="0 0 0"/>
            <material name="blue">
                <color rgba="0 0 1.0 1.0"/>
            </material>
        </visual>
    </link>

</robot>
