<?xml version="1.0" ?>
<!-- =================================================================================== -->
<!-- |    This document was autogenerated by xacro from 2link.xacro                    | -->
<!-- |    EDITING THIS FILE BY HAND IS NOT RECOMMENDED                                 | -->
<!-- =================================================================================== -->
<robot name="gymnast_robot" xmlns:xacro="http://ros.org/wiki/xacro">
  <!--color parameter-->
  <material name="red">
    <color rgba="1 0 0 1"/>
  </material>
  <material name="green">
    <color rgba="0 1 0 1"/>
  </material>
  <material name="blue">
    <color rgba="0 0 1 1"/>
  </material>
  <link name="world"/>
  <joint name="world_joint" type="fixed">
    <parent link="world"/>
    <child link="base_link"/>
    <origin rpy="0 0 0" xyz="0 0 0"/>
  </joint>
  <link name="base_link">
    <visual>
      <geometry>
        <box size="0.1 0.1 3"/>
      </geometry>
      <origin rpy="0 0 0" xyz="0 -0.5 1.5"/>
      <material name="blue"/>
    </visual>
    <inertial>
      <origin rpy="" xyz="0 -0.5 1.5"/>
      <mass value="1"/>
      <inertia ixx="0" ixy="0" ixz="0" iyy="0" iyz="0" izz="0"/>
    </inertial>
    <collision>
      <geometry>
        <box size="0.1 0.1 3"/>
      </geometry>
      <origin rpy="0 0 0" xyz="0 -0.5 1.5"/>
    </collision>
  </link>
  <gazebo refernce="base_link">
    <material>Gazebo/Blue</material>
    ?
    
  </gazebo>
  <joint name="system_joint" type="fixed">
    <parent link="base_link"/>
    <child link="bar_link"/>
    <origin rpy="0 0 0" xyz="0 0 3"/>
  </joint>
  <link name="bar_link">
    <visual>
      <geometry>
        <cylinder length="1.0" radius="0.05"/>
      </geometry>
      <origin rpy="1.57 0 0" xyz="0 0 0"/>
      <material name="blue"/>
    </visual>
    <collision>
      <geometry>
        <cylinder length="1.0" radius="0.05"/>
      </geometry>
      <origin rpy="1.57 0 0" xyz="0 0 0"/>
    </collision>
    <inertial>
      <mass value="0"/>
      <inertia ixx="0" ixy="0" ixz="0" iyy="0" iyz="0" izz="0"/>
      <origin rpy="1.57 0 0" xyz="0 0 0"/>
    </inertial>
  </link>
  <gazebo reference="base_link">
    <material>Gazebo/Orange</material>
  </gazebo>
  <joint name="1st_joint" type="continuous">
    <parent link="base_link"/>
    <child link="1st"/>
    <origin rpy="0 0 0" xyz="0 0 3"/>
    <limit effort="0" velocity="1"/>
    <axis xyz="0 1 0"/>
    <dynamics damping="0.0"/>
  </joint>
  <link name="1st">
    <visual>
      <geometry>
        <box size="0.1 0.3 1.0"/>
      </geometry>
      <origin rpy="0 0 0" xyz="0 0 0.5"/>
      <material name="red"/>
    </visual>
    <inertial>
      <origin rpy="0 0 0" xyz="0 0 0"/>
      <mass value="0.5"/>
      <inertia ixx="0.01" ixy="0" ixz="0" iyy="0.01" iyz="0" izz="0.01"/>
    </inertial>
    <collision>
      <geometry>
        <box size="0.1 0.3 1.0"/>
      </geometry>
      <origin rpy="0 0 0" xyz="0 0 0.5"/>
    </collision>
  </link>
  <gazebo reference="1st">
    <material>Gazebo/Red</material>
  </gazebo>
  <joint name="1st_fixed" type="fixed">
    <parent link="1st"/>
    <child link="1st_link"/>
  </joint>
  <link name="1st_link">
    <visual>
      <geometry>
        <cylinder length="0.3" radius="0.05"/>
      </geometry>
      <origin rpy="1.57 0 0" xyz="0 0 1.0"/>
      <material name="red"/>
    </visual>
    <collision>
      <geometry>
        <cylinder length="0.3" radius="0.05"/>
      </geometry>
      <origin rpy="1.57 0 0" xyz="0 0 1.0"/>
    </collision>
    <inertial>
      <mass value="0"/>
      <inertia ixx="0" ixy="0" ixz="0" iyy="0" iyz="0" izz="0"/>
    </inertial>
  </link>
  <gazebo reference="1st_link">
    <material>Gazebo/Red</material>
  </gazebo>
  <joint name="2nd_joint" type="revolute">
    <parent link="1st_link"/>
    <child link="2nd"/>
    <origin rpy="0 0 0" xyz="0 0 1.0"/>
    <limit effort="1" lower="-1.57" upper="1.57" velocity="1"/>
    <axis xyz="0 1 0"/>
    <dynamics damping="0.0"/>
  </joint>
  <link name="2nd">
    <visual>
      <geometry>
        <box size="0.1 0.3 1.0"/>
      </geometry>
      <origin rpy="0 0 0" xyz="0 0 0.5"/>
      <material name="green"/>
    </visual>
    <inertial>
      <origin rpy="0 0 0" xyz="0 0 0"/>
      <mass value="0.5"/>
      <inertia ixx="0.01" ixy="0" ixz="0" iyy="0.01" iyz="0" izz="0.01"/>
    </inertial>
    <collision>
      <geometry>
        <box size="0.1 0.3 1.0"/>
      </geometry>
      <origin rpy="0 0 0" xyz="0 0 0.5"/>
    </collision>
  </link>
  <gazebo reference="2nd">
    <material>Gazebo/Red</material>
  </gazebo>
  <joint name="2nd_fixed" type="fixed">
    <parent link="2nd"/>
    <child link="2nd_link"/>
  </joint>
  <link name="2nd_link">
    <visual>
      <geometry>
        <cylinder length="0.3" radius="0.05"/>
      </geometry>
      <origin rpy="1.57 0 0" xyz="0 0 1.0"/>
      <material name="green"/>
    </visual>
    <collision>
      <geometry>
        <cylinder length="0.3" radius="0.05"/>
      </geometry>
      <origin rpy="1.57 0 0" xyz="0 0 1.0"/>
    </collision>
    <inertial>
      <mass value="0"/>
      <inertia ixx="0" ixy="0" ixz="0" iyy="0" iyz="0" izz="0"/>
    </inertial>
  </link>
  <gazebo reference="2nd_link">
    <material>Gazebo/Red</material>
  </gazebo>
  <joint name="3rd_joint" type="revolute">
    <parent link="2nd_link"/>
    <child link="3rd"/>
    <origin rpy="0 0 0" xyz="0 0 1.0"/>
    <limit effort="1" lower="-1.57" upper="1.57" velocity="1"/>
    <axis xyz="0 1 0"/>
    <dynamics damping="0.0"/>
  </joint>
  <link name="3rd">
    <visual>
      <geometry>
        <box size="0.1 0.3 1.0"/>
      </geometry>
      <origin rpy="0 0 0" xyz="0 0 0.5"/>
      <material name="blue"/>
    </visual>
    <inertial>
      <origin rpy="0 0 0" xyz="0 0 0"/>
      <mass value="0.5"/>
      <inertia ixx="0.01" ixy="0" ixz="0" iyy="0.01" iyz="0" izz="0.01"/>
    </inertial>
    <collision>
      <geometry>
        <box size="0.1 0.3 1.0"/>
      </geometry>
      <origin rpy="0 0 0" xyz="0 0 0.5"/>
    </collision>
  </link>
  <gazebo reference="3rd">
    <material>Gazebo/Red</material>
  </gazebo>
  <joint name="3rd_fixed" type="fixed">
    <parent link="3rd"/>
    <child link="3rd_link"/>
  </joint>
  <link name="3rd_link">
    <visual>
      <geometry>
        <cylinder length="0.3" radius="0.05"/>
      </geometry>
      <origin rpy="1.57 0 0" xyz="0 0 1.0"/>
      <material name="blue"/>
    </visual>
    <collision>
      <geometry>
        <cylinder length="0.3" radius="0.05"/>
      </geometry>
      <origin rpy="1.57 0 0" xyz="0 0 1.0"/>
    </collision>
    <inertial>
      <mass value="0"/>
      <inertia ixx="0" ixy="0" ixz="0" iyy="0" iyz="0" izz="0"/>
    </inertial>
  </link>
  <gazebo reference="3rd_link">
    <material>Gazebo/Red</material>
  </gazebo>
  <gazebo>
    <plugin filename="libgazebo_ros_control.so" name="gazebo_ros_control">
      <robotNamespace>/gymnast_robot</robotNamespace>
    </plugin>
  </gazebo>
</robot>

