<?xml version="1.0" ?>
<!-- =================================================================================== -->
<!-- |    This document was autogenerated by xacro from acrobat_robot_IB.xacro         | -->
<!-- |    EDITING THIS FILE BY HAND IS NOT RECOMMENDED                                 | -->
<!-- =================================================================================== -->
<robot name="IB_robot" xmlns:xacro="http://www.ros.org/wiki/xacro">
  <material name="black">
    <color rgba="0.0 0.0 0.0 1.0"/>
  </material>
  <material name="blue">
    <color rgba="0.0 0.0 0.8 1.0"/>
  </material>
  <material name="green">
    <color rgba="0.0 0.8 0.0 1.0"/>
  </material>
  <material name="grey">
    <color rgba="0.2 0.2 0.2 1.0"/>
  </material>
  <material name="orange">
    <color rgba="1.0 0.423529411765 0.0392156862745 1.0"/>
  </material>
  <material name="brown">
    <color rgba="0.870588235294 0.811764705882 0.764705882353 1.0"/>
  </material>
  <material name="red">
    <color rgba="0.8 0.0 0.0 1.0"/>
  </material>
  <material name="white">
    <color rgba="1.0 1.0 1.0 1.0"/>
  </material>
  <!-- ros_control plugin -->
  <gazebo>
    <plugin filename="libgazebo_ros_control.so" name="gazebo_ros_control">
      <robotNamespace>/IB_robot</robotNamespace>
      <robotSimType>gazebo_ros_control/DefaultRobotHWSim</robotSimType>
    </plugin>
  </gazebo>
  <!-- base link -->
  <gazebo reference="base_link">
    <material>Gazebo/White</material>
  </gazebo>
  <!-- Link1 -->
  <gazebo reference="1st_link">
    <material>Gazebo/Orange</material>
  </gazebo>
  <!-- Link2 -->
  <gazebo reference="2nd_link">
    <material>Gazebo/Green</material>
  </gazebo>
  <!-- fixed base_link -->
  <link name="world"/>
  <joint name="world_fixed" type="fixed">
    <parent link="world"/>
    <child link="base"/>
  </joint>
  <!-- base_link -->
  <link name="base">
    <visual>
      <!-- visual config -->
      <origin rpy="0 0 0" xyz="0 0 5.3015"/>
      <material name="white"/>
      <geometry>
        <box size="0.5 0.5 10.603"/>
      </geometry>
    </visual>
    <collision>
      <!-- Gazebo collision config -->
      <origin rpy="0 0 0" xyz="0 0 5.3015"/>
      <geometry>
        <box size="0.5 0.5 10.603"/>
      </geometry>
    </collision>
    <inertial>
      <origin rpy="0 0 0" xyz="0 0 5.3015"/>
      <mass value="100"/>
      <inertia ixx="10" ixy="0" ixz="0" iyy="10" iyz="0" izz="10"/>
    </inertial>
  </link>
  <joint name="1st_link_joint" type="continuous">
    <parent link="base"/>
    <child link="1st_link"/>
    <origin rpy="0 0 0" xyz="0 0.05 0"/>
    <limit effort="100" velocity="100"/>
    <axis xyz="0 1 0"/>
    <dynamics damping="0.1"/>
  </joint>
  <link name="1st_link">
    <!-- visual config -->
    <visual>
      <origin rpy="0 0 0" xyz="0 0 0.169"/>
      <material name="orange"/>
      <geometry>
        <box size="0.05 0.05 0.338"/>
      </geometry>
    </visual>
    <!-- Gazebo collision config -->
    <collision>
      <origin rpy="0 0 0" xyz="0 0 0.169"/>
      <geometry>
        <box size="0.05 0.05 0.338"/>
      </geometry>
    </collision>
    <!-- inertial config -->
    <inertial>
      <origin rpy="0 0 0" xyz="{comx1} 0.0 0.232"/>
      <mass value="0.71"/>
      <inertia ixx="0.01" ixy="0" ixz="0" iyy="0.01" iyz="0" izz="0.0058"/>
    </inertial>
  </link>
</robot>

